Traceback (most recent call last):
  File "/usr/local/lib/python3.7/site-packages/django/core/management/base.py", line 323, in run_from_argv
    self.execute(*args, **cmd_options)
  File "/usr/local/lib/python3.7/site-packages/django/core/management/commands/runserver.py", line 60, in execute
    super().execute(*args, **options)
  File "/usr/local/lib/python3.7/site-packages/django/core/management/base.py", line 364, in execute
    output = self.handle(*args, **options)
  File "/usr/local/lib/python3.7/site-packages/django/core/management/commands/runserver.py", line 67, in handle
    if not settings.DEBUG and not settings.ALLOWED_HOSTS:
  File "/usr/local/lib/python3.7/site-packages/django/conf/__init__.py", line 79, in __getattr__
    self._setup(name)
  File "/usr/local/lib/python3.7/site-packages/django/conf/__init__.py", line 66, in _setup
    self._wrapped = Settings(settings_module)
  File "/usr/local/lib/python3.7/site-packages/django/conf/__init__.py", line 157, in __init__
    mod = importlib.import_module(self.SETTINGS_MODULE)
  File "/usr/local/lib/python3.7/importlib/__init__.py", line 127, in import_module
    return _bootstrap._gcd_import(name[level:], package, level)
  File "<frozen importlib._bootstrap>", line 1006, in _gcd_import
  File "<frozen importlib._bootstrap>", line 983, in _find_and_load
  File "<frozen importlib._bootstrap>", line 965, in _find_and_load_unlocked
ModuleNotFoundError: No module named 'mysite.settings'

During handling of the above exception, another exception occurred:

Traceback (most recent call last):
  File "manage.py", line 21, in <module>
    main()
  File "manage.py", line 17, in main
    execute_from_command_line(sys.argv)
  File "/usr/local/lib/python3.7/site-packages/django/core/management/__init__.py", line 381, in execute_from_command_line
    utility.execute()
  File "/usr/local/lib/python3.7/site-packages/django/core/management/__init__.py", line 375, in execute
    self.fetch_command(subcommand).run_from_argv(self.argv)
  File "/usr/local/lib/python3.7/site-packages/django/core/management/base.py", line 336, in run_from_argv
    connections.close_all()
  File "/usr/local/lib/python3.7/site-packages/django/db/utils.py", line 219, in close_all
    for alias in self:
  File "/usr/local/lib/python3.7/site-packages/django/db/utils.py", line 213, in __iter__
    return iter(self.databases)
  File "/usr/local/lib/python3.7/site-packages/django/utils/functional.py", line 80, in __get__
    res = instance.__dict__[self.name] = self.func(instance)
  File "/usr/local/lib/python3.7/site-packages/django/db/utils.py", line 147, in databases
    self._databases = settings.DATABASES
  File "/usr/local/lib/python3.7/site-packages/django/conf/__init__.py", line 79, in __getattr__
    self._setup(name)
  File "/usr/local/lib/python3.7/site-packages/django/conf/__init__.py", line 66, in _setup
    self._wrapped = Settings(settings_module)
  File "/usr/local/lib/python3.7/site-packages/django/conf/__init__.py", line 157, in __init__
    mod = importlib.import_module(self.SETTINGS_MODULE)
  File "/usr/local/lib/python3.7/importlib/__init__.py", line 127, in import_module
    return _bootstrap._gcd_import(name[level:], package, level)
  File "<frozen importlib._bootstrap>", line 1006, in _gcd_import
  File "<frozen importlib._bootstrap>", line 983, in _find_and_load
  File "<frozen importlib._bootstrap>", line 965, in _find_and_load_unlocked
ModuleNotFoundError: No module named 'mysite.settings'
Traceback (most recent call last):
  File "/usr/local/lib/python3.7/site-packages/django/core/management/base.py", line 323, in run_from_argv
    self.execute(*args, **cmd_options)
  File "/usr/local/lib/python3.7/site-packages/django/core/management/commands/runserver.py", line 60, in execute
    super().execute(*args, **options)
  File "/usr/local/lib/python3.7/site-packages/django/core/management/base.py", line 364, in execute
    output = self.handle(*args, **options)
  File "/usr/local/lib/python3.7/site-packages/django/core/management/commands/runserver.py", line 67, in handle
    if not settings.DEBUG and not settings.ALLOWED_HOSTS:
  File "/usr/local/lib/python3.7/site-packages/django/conf/__init__.py", line 79, in __getattr__
    self._setup(name)
  File "/usr/local/lib/python3.7/site-packages/django/conf/__init__.py", line 66, in _setup
    self._wrapped = Settings(settings_module)
  File "/usr/local/lib/python3.7/site-packages/django/conf/__init__.py", line 157, in __init__
    mod = importlib.import_module(self.SETTINGS_MODULE)
  File "/usr/local/lib/python3.7/importlib/__init__.py", line 127, in import_module
    return _bootstrap._gcd_import(name[level:], package, level)
  File "<frozen importlib._bootstrap>", line 1006, in _gcd_import
  File "<frozen importlib._bootstrap>", line 983, in _find_and_load
  File "<frozen importlib._bootstrap>", line 965, in _find_and_load_unlocked
ModuleNotFoundError: No module named 'mysite.settings'

During handling of the above exception, another exception occurred:

Traceback (most recent call last):
  File "manage.py", line 21, in <module>
    main()
  File "manage.py", line 17, in main
    execute_from_command_line(sys.argv)
  File "/usr/local/lib/python3.7/site-packages/django/core/management/__init__.py", line 381, in execute_from_command_line
    utility.execute()
  File "/usr/local/lib/python3.7/site-packages/django/core/management/__init__.py", line 375, in execute
    self.fetch_command(subcommand).run_from_argv(self.argv)
  File "/usr/local/lib/python3.7/site-packages/django/core/management/base.py", line 336, in run_from_argv
    connections.close_all()
  File "/usr/local/lib/python3.7/site-packages/django/db/utils.py", line 219, in close_all
    for alias in self:
  File "/usr/local/lib/python3.7/site-packages/django/db/utils.py", line 213, in __iter__
    return iter(self.databases)
  File "/usr/local/lib/python3.7/site-packages/django/utils/functional.py", line 80, in __get__
    res = instance.__dict__[self.name] = self.func(instance)
  File "/usr/local/lib/python3.7/site-packages/django/db/utils.py", line 147, in databases
    self._databases = settings.DATABASES
  File "/usr/local/lib/python3.7/site-packages/django/conf/__init__.py", line 79, in __getattr__
    self._setup(name)
  File "/usr/local/lib/python3.7/site-packages/django/conf/__init__.py", line 66, in _setup
    self._wrapped = Settings(settings_module)
  File "/usr/local/lib/python3.7/site-packages/django/conf/__init__.py", line 157, in __init__
    mod = importlib.import_module(self.SETTINGS_MODULE)
  File "/usr/local/lib/python3.7/importlib/__init__.py", line 127, in import_module
    return _bootstrap._gcd_import(name[level:], package, level)
  File "<frozen importlib._bootstrap>", line 1006, in _gcd_import
  File "<frozen importlib._bootstrap>", line 983, in _find_and_load
  File "<frozen importlib._bootstrap>", line 965, in _find_and_load_unlocked
ModuleNotFoundError: No module named 'mysite.settings'
